<mujoco model="humanoid">
    <include file="../../misc/skybox.xml" />
    <include file="../../misc/visual.xml" />
    <include file="../../misc/materials.xml" />
    <compiler angle="degree" coordinate="local" inertiafromgeom="true"/>
    <default>
        <joint armature="1" damping="1" limited="true"/>
        <geom conaffinity="0" condim="3" contype="1" density="1000" friction=".7 .1 .1" material="self" />
        <motor ctrllimited="true" ctrlrange="-1 1"/>
    </default>
    <option integrator="RK4" timestep="0.002" />
    <visual>
        <map fogend="5" fogstart="3"/>
    </visual>
    <worldbody>
        <light cutoff="100" diffuse="1 1 1" dir="-1 -0 -1.5" directional="true" exponent="1" pos="0 0 1.3" specular=".1 .1 .1"/>
        <geom conaffinity="1" condim="3" material="grid" name="floor" pos="0 0 0" size="200 200 0.125" type="plane"/>
        <!-- <geom condim="3" material="MatPlane" name="floor" pos="0 0 0" size="10 10 0.125" type="plane"/>-->
        <body name="torso" pos="0 0 1.234625">
            <camera name="tilted" mode="trackcom" pos="3.6 4 -0.2" xyaxes="1 -.9 0 0 0 -1"/>
            <camera name="track" mode="trackcom" pos="0 4 0" xyaxes="1 0 0 0 0 -1"/>
            <joint armature="0" damping="0" limited="false" name="root" pos="0 0 0" stiffness="0" type="free"/>
            <!-- <joint armature="0.02" axis="1 0 0" damping="0" name="root_x" pos="0 0 0" stiffness="0" type="hinge" limited="false"/>
            <joint armature="0.02" axis="0 0 1" damping="0" name="root_z" pos="0 0 0" ref="1.25" stiffness="0" type="hinge" limited="false"/>
            <joint armature="0.02" axis="0 1 0" damping="0" name="root_y" pos="0 0 1.1" stiffness="0" type="hinge" limited="false"/> -->
            <geom fromto="0 -.07 0.165375 0 .07 0.165375" name="torso1" size="0.07" type="capsule"/>
            <geom name="head" pos="0 0 0.355375" size=".09" type="sphere"/>
            <geom fromto="-.01 -.06 0.045375 -.01 .06 0.045375" name="uwaist" size="0.06" type="capsule"/>
            <!-- <body name="lwaist" pos="-.01 0 -0.260" quat="1.000 0 -0.002 0"> -->
            <geom fromto="-.01 -.06 -0.094625 -.01 .06 -0.094625" name="lwaist" size="0.06" quat="1.000 0 -0.002 0" type="capsule"/>
            <!-- <joint armature="0.02" axis="0 0 1" damping="5" name="lwaist_joint_z" pos="0 0 0.065" range="-45 45" stiffness="20" type="hinge"/>
            <joint armature="0.02" axis="0 1 0" damping="5" name="lwaist_joint_y" pos="0 0 0.065" range="-75 30" stiffness="10" type="hinge"/>
            <joint armature="0.02" axis="1 0 0" damping="5" name="lwaist_joint_x" pos="0 0 0.065" range="-35 35" stiffness="10" type="hinge"/> -->

            <geom fromto="-.02 -.07 -0.259625 -.02 .07 -0.259625" name="butt" size="0.09" quat="1.000 0 -0.002 0" type="capsule"/>
            
            <body name="right_thigh" pos="0 -0.1 -0.299625">
                <joint armature="0.01" axis="1 0 0" damping="5" name="right_thigh_joint_x" pos="0 0 0" range="-25 5" stiffness="10" type="hinge"/>
                <joint armature="0.0080" axis="0 -1 0" damping="5" name="right_thigh_joint_y" pos="0 0 0" range="-20 110" stiffness="20" type="hinge"/>
                <joint armature="0.01" axis="0 0 1" damping="5" name="right_thigh_joint_z" pos="0 0 0" range="-60 35" stiffness="10" type="hinge"/>
                <geom fromto="0 0 0 0 0.01 -.34" name="right_thigh1" size="0.06" type="capsule"/>
                <body name="right_shin" pos="0 0.01 -0.403">
                    <joint armature="0.0060" axis="1 0 0" name="right_shin_joint_x" pos="0 0 .02" range="-1 1" stiffness="1" type="hinge"/>
                    <joint armature="0.0060" axis="0 -1 0" name="right_shin_joint_y" pos="0 0 .02" range="-160 -2" stiffness="1" type="hinge"/>
                    <joint armature="0.0060" axis="0 0 1" name="right_shin_joint_z" pos="0 0 .02" range="-1 1" stiffness="1" type="hinge"/>
                    <geom fromto="0 0 0 0 0 -.3" name="right_shin1" size="0.049" type="capsule"/>
                    <geom name="right_foot" pos="0 0 -0.35" size="0.075" type="sphere"/>
                </body>
            </body>
            <body name="left_thigh" pos="0 0.1 -0.299625">
                <joint armature="0.01" axis="-1 0 0" damping="5" name="left_thigh_joint_x" pos="0 0 0" range="-25 5" stiffness="10" type="hinge"/>
              <joint armature="0.01" axis="0 -1 0" damping="5" name="left_thigh_joint_y" pos="0 0 0" range="-20 110" stiffness="20" type="hinge"/>
                <joint armature="0.01" axis="0 0 -1" damping="5" name="left_thigh_joint_z" pos="0 0 0" range="-60 35" stiffness="10" type="hinge"/>

                <geom fromto="0 0 0 0 -0.01 -.34" name="left_thigh1" size="0.06" type="capsule"/>
                <body name="left_shin" pos="0 -0.01 -0.403">
                    <joint armature="0.0060" axis="-1 0 0" name="left_shin_joint_x" pos="0 0 .02" range="-1 1" stiffness="1" type="hinge"/>
                    <joint armature="0.0060" axis="0 -1 0" name="left_shin_joint_y" pos="0 0 .02" range="-160 -2" stiffness="1" type="hinge"/>
                    <joint armature="0.0060" axis="0 0 -1" name="left_shin_joint_z" pos="0 0 .02" range="-1 1" stiffness="1" type="hinge"/>
                    <geom fromto="0 0 0 0 0 -.3" name="left_shin1" size="0.049" type="capsule"/>
                    <geom name="left_foot" type="sphere" size="0.075" pos="0 0 -0.35"/>
                </body>
            </body>
            <!-- </body> -->

            <body name="right_upper_arm" pos="0 -0.17 0.225375">
                <joint armature="0.0068" axis="2 1 1" name="right_upper_arm_joint_x" pos="0 0 0" range="-85 60" stiffness="1" type="hinge"/>
                <joint armature="0.0051" axis="0 -1 1" name="right_upper_arm_joint_y" pos="0 0 0" range="-85 60" stiffness="1" type="hinge"/>
                <joint armature="0.0051" axis="0 0 1" name="right_upper_arm_joint_z" pos="0 0 0" range="-1 1" stiffness="1" type="hinge"/>
                <geom fromto="0 0 0 .16 -.16 -.16" name="right_uarm1" size="0.04 0.16" type="capsule"/>
                <body name="right_lower_arm" pos=".18 -.18 -.18">
                    <joint armature="0.0028" axis="1 0 0" name="right_lower_arm_joint_x" pos="0 0 0" range="-1 1" stiffness="0" type="hinge"/>
                    <joint armature="0.0028" axis="0 -1 1" name="right_lower_arm_joint_y" pos="0 0 0" range="-90 50" stiffness="0" type="hinge"/>
                    <joint armature="0.0028" axis="0 0 1" name="right_lower_arm_joint_z" pos="0 0 0" range="-1 1" stiffness="0" type="hinge"/>
                    <geom fromto="0.01 0.01 0.01 .17 .17 .17" name="right_larm" size="0.031" type="capsule"/>
                    <geom name="right_hand" pos=".18 .18 .18" size="0.04" type="sphere"/>
                    <camera pos="0 0 0"/>
                </body>
            </body>
            
        </body>
    </worldbody>


    <actuator>
        <!-- <motor gear="100" joint="lwaist_joint_x" name="lwaist_joint_x"/>
        <motor gear="100" joint="lwaist_joint_y" name="lwaist_joint_y"/>
        <motor gear="100" joint="lwaist_joint_z" name="lwaist_joint_z"/> -->
        <motor gear="100" joint="right_thigh_joint_x" name="right_thigh_joint_x"/>
        <motor gear="300" joint="right_thigh_joint_y" name="right_thigh_joint_y"/>
        <motor gear="100" joint="right_thigh_joint_z" name="right_thigh_joint_z"/>
        <motor gear="0" joint="right_shin_joint_x" name="right_shin_joint_x"/>
        <motor gear="200" joint="right_shin_joint_y" name="right_shin_joint_y"/>
        <motor gear="0" joint="right_shin_joint_z" name="right_shin_joint_z"/>
        <motor gear="100" joint="left_thigh_joint_x" name="left_thigh_joint_x"/>
        <motor gear="300" joint="left_thigh_joint_y" name="left_thigh_joint_y"/>
        <motor gear="100" joint="left_thigh_joint_z" name="left_thigh_joint_z"/>
        <motor gear="0" joint="left_shin_joint_x" name="left_shin_joint_x"/>
        <motor gear="200" joint="left_shin_joint_y" name="left_shin_joint_y"/>
        <motor gear="0" joint="left_shin_joint_z" name="left_shin_joint_z"/>
        <motor gear="25" joint="right_upper_arm_joint_x" name="right_upper_arm_joint_x"/>
        <motor gear="25" joint="right_upper_arm_joint_y" name="right_upper_arm_joint_y"/>
        <motor gear="0" joint="right_upper_arm_joint_z" name="right_upper_arm_joint_z"/>
        <motor gear="0" joint="right_lower_arm_joint_x" name="right_lower_arm_joint_x"/>
        <motor gear="25" joint="right_lower_arm_joint_y" name="right_lower_arm_joint_y"/>
        <motor gear="0" joint="right_lower_arm_joint_z" name="right_lower_arm_joint_z"/>
    </actuator>
</mujoco>
