<mujoco model="walker_generic">
   <include file="../../misc/skybox.xml" />
   <include file="../../misc/visual.xml" />
   <include file="../../misc/materials.xml" />
   <compiler angle="degree" coordinate="global" inertiafromgeom="true" />
   <default>
      <joint armature="0.01" damping=".1" limited="true" />
      <geom conaffinity="0" condim="3" contype="1" density="1000" friction=".7 .1 .1" material="self" />
   </default>
   <option integrator="RK4" timestep="0.002" />
      <actuator>
         <motor ctrllimited="true" ctrlrange="-1.0 1.0" gear="100" joint="right_thigh_joint_x" name="right_thigh_joint_x"/>
         <motor ctrllimited="true" ctrlrange="-1.0 1.0" gear="100" joint="right_thigh_joint_y" name="right_thigh_joint_y"/>
         <motor ctrllimited="true" ctrlrange="-1.0 1.0" gear="100" joint="right_thigh_joint_z" name="right_thigh_joint_z"/>

         <motor ctrllimited="true" ctrlrange="-1.0 1.0" gear="0" joint="right_shin_joint_x" name="right_shin_joint_x"/>
         <motor ctrllimited="true" ctrlrange="-1.0 1.0" gear="100" joint="right_shin_joint_y" name="right_shin_joint_y"/>
         <motor ctrllimited="true" ctrlrange="-1.0 1.0" gear="0" joint="right_shin_joint_z" name="right_shin_joint_z"/>

      </actuator>
      <worldbody>
         <light cutoff="100" diffuse="1 1 1" dir="-1 -0 -1.5" directional="true" exponent="1" pos="0 0 1.3" specular=".1 .1 .1" />
         <geom conaffinity="1" condim="3" material="grid" name="floor" pos="0 0 0" size="40 40 40" type="plane" />
         <body name="torso" pos="0 0 1.6">
            <camera mode="trackcom" name="tilted" pos="2.7 3 1" xyaxes="1 -.9 0 0 0 -1" />
            <camera mode="trackcom" name="track" pos="0 3 1" xyaxes="1 0 0 0 0 -1" />
            <joint armature="0" damping="0" limited="false" name="root" pos="0 0 0" stiffness="0" type="free"/>
            <!-- <joint armature="0" axis="1 0 0" damping="0" limited="false" name="rootx" pos="0 0 0" stiffness="0" type="slide" />
            <joint armature="0" axis="0 0 1" damping="0" limited="false" name="rootz" pos="0 0 0" ref="1.25" stiffness="0" type="slide" />
            <joint armature="0" axis="0 1 0" damping="0" limited="false" name="rooty" pos="0 0 1.25" stiffness="0" type="hinge" /> -->
            <geom friction="0.9" fromto="0 0 1.6 0 0 1.0" name="torso_geom" size="0.07" type="capsule" />
            <body name="right_thigh" pos="0 0 1.0">
               <geom friction="0.9" fromto="0 0 1.0 0 0 0.52" name="right_thigh" size="0.05600000000000001" type="capsule" />
               <joint axis="1 0 0" name="right_thigh_joint_x" pos="0 0 1.0" range="-25 5" type="hinge" />
               <joint axis="0 -1 0" name="right_thigh_joint_y" pos="0 0 1.0" range="-20 110" type="hinge" />
               <joint axis="0 0 1" name="right_thigh_joint_z" pos="0 0 1.0" range="-60 35" type="hinge" />
               <body name="right_shin" pos="0 0 0.52">
                  <geom friction="0.9" fromto="0 0 0.52 0 0 0.136" name="right_shin" size="0.044800000000000006" type="capsule" />
                  <joint axis="1 0 0" name="right_shin_joint_x" pos="0 0 0.52" range="-1 1" type="hinge" />
                  <joint axis="0 -1 0" name="right_shin_joint_y" pos="0 0 0.52" range="-160 -2" type="hinge" />
                  <joint axis="0 0 1" name="right_shin_joint_z" pos="0 0 0.52" range="-1 1" type="hinge" />
               </body>
            </body>
         </body>
      </worldbody>
</mujoco>