<mujoco model="cheetah">
  <include file="../../misc/skybox.xml" />
  <include file="../../misc/visual.xml" />
  <include file="../../misc/materials.xml" />
  <compiler angle="degree" coordinate="local" inertiafromgeom="true"/>
  <default>
    <joint armature=".1" damping=".01" limited="true" solimplimit="0 .8 .03" solreflimit=".02 1" stiffness="8"/>
    <geom conaffinity="0" condim="3" contype="1" friction=".4 .1 .1" solimp="0.0 0.8 0.01" solref="0.02 1" material="self"/>
    <motor ctrllimited="true" ctrlrange="-1 1"/>
  </default>
  <size nstack="300000" nuser_geom="1"/>
  <option gravity="0 0 -9.81" timestep="0.01"/>

  <worldbody>
    <light cutoff="100" diffuse="1 1 1" dir="-1 -0 -1.5" directional="true" exponent="1" pos="0 0 1.3" specular=".1 .1 .1"/>
    <geom conaffinity="1" condim="3" material="grid" name="floor" pos="0 0 0" size="200 200 0.125" type="plane"/>
    <body name="torso" pos="0 0 .7">
      <camera mode="trackcom" name="tilted" pos="2.9 3.2 0.3" xyaxes="1 -.9 0 0 0 -1" />
      <camera name="track" mode="trackcom" pos="0 3 0.3" xyaxes="1 0 0 0 0 -1"/>
      <joint armature="0" damping="0" limited="false" name="root" pos="0 0 0" stiffness="0" type="free"/>
      <!-- <joint armature="0" axis="1 0 0" damping="0" limited="false" name="rootx" pos="0 0 0" stiffness="0" type="slide"/>
      <joint armature="0" axis="0 0 1" damping="0" limited="false" name="rootz" pos="0 0 0" stiffness="0" type="slide"/>
      <joint armature="0" axis="0 1 0" damping="0" limited="false" name="rooty" pos="0 0 0" stiffness="0" type="hinge"/> -->
      <!-- <geom fromto="-.5 0 0 .5 0 0" name="torso" size="0.046" type="capsule"/> -->
      
      <geom fromto="0.4 -.08 0 0.4 .08 0" name="torso1" size="0.07" type="capsule"/>
      <geom fromto="0.28 -.07 -0.01 0.28 .07 -0.01" name="waist1" size="0.06" type="capsule"/>
      <geom fromto="0.14 -.07 -0.01 0.14 .07 -0.01" name="waist2" size="0.06" quat="1.000 0 -0.002 0" type="capsule"/>
      <geom fromto="0 -.06 -0.01  0 .06 -0.01" name="waist3" size="0.06" quat="1.000 0 -0.002 0" type="capsule"/>
      <geom fromto="-.14 -.06 -0.01 -.14 .06 -0.01" name="waist4" size="0.06" quat="1.000 0 -0.002 0" type="capsule"/>
      <geom fromto="-.28 -.06 -0.01 -.28 .06 -0.01" name="waist5" size="0.06" quat="1.000 0 -0.002 0" type="capsule"/>
      <geom fromto="-.445 -.09 -.02 -.445 .09 -.02" name="butt" size="0.09" quat="1.000 0 -0.002 0" type="capsule"/>


      <geom name="head" pos=".5 0 0.1" size=".09" type="sphere"/>

      <body name="upper_tail" pos="-.445 0 0">
        <geom axisangle="0 1 0 -90" name="upper_tail" pos="-0.25 0 0.0" size="0.04 .25" type="capsule"/>
        <joint axis="1 0 0" damping="3.5" name="upper_tail_joint_x" pos="0 0 0" range="-20 20" stiffness="0" type="hinge"/>
        <joint axis="0 -1 0" damping="3.5" name="upper_tail_joint_y" pos="0 0 0" range="-80 80" stiffness="0" type="hinge"/>
        <joint axis="0 0 1" damping="3.5" name="upper_tail_joint_z" pos="0 0 0" range="-1 1" stiffness="0" type="hinge"/>
        <geom axisangle="0 1 0 -45" name="lower_tail" pos="-0.55 0 0.05" size="0.04 .07" type="capsule"/>
      </body>


      <!-- <site name='tip'  pos='.15 0 .11'/>-->
      <body name="right_bthigh" pos="-.445 -.12 0">
        <joint axis="1 0 0" damping="6" name="right_bthigh_joint_x" pos="0 0 0" range="-10 0" stiffness="240" type="hinge"/>
        <joint axis="0 -1 0" damping="6" name="right_bthigh_joint_y" pos="0 0 0" range="-60 30" stiffness="240" type="hinge"/>
        <joint axis="0 0 1" damping="6" name="right_bthigh_joint_z" pos="0 0 0" range="-15 5" stiffness="240" type="hinge"/>
        <geom axisangle="0 1 0 -217.7239621497" name="right_bthigh" pos=".1 0 -.13" size="0.06 .145" type="capsule"/>
        <body name="right_bshin" pos=".16 0 -.25">
          <joint axis="1 0 0" damping="4.5" name="right_bshin_joint_x" pos="0 0 0" range="-1 1" stiffness="180" type="hinge"/>
          <joint axis="0 -1 0" damping="4.5" name="right_bshin_joint_y" pos="0 0 0" range="-45 45" stiffness="180" type="hinge"/>
          <joint axis="0 0 1" damping="4.5" name="right_bshin_joint_z" pos="0 0 0" range="-1 1" stiffness="180" type="hinge"/>
          <geom axisangle="0 1 0 -116.3104324116" name="right_bshin" pos="-.14 0 -.07" size="0.046 .15" type="capsule"/>
          <!-- <geom name="right_right_bfoot" type="sphere" size="0.06" pos="-0.310 0 -0.155"/> -->
          <body name="right_bfoot" pos="-.28 0 -.14">
            <joint axis="1 0 0" damping="3" name="right_bfoot_joint_x" pos="0 0 0" range="-1 1" stiffness="120" type="hinge"/>
            <joint axis="0 -1 0" damping="3" name="right_bfoot_joint_y" pos="0 0 0" range="-45 25" stiffness="120" type="hinge"/>
            <joint axis="0 0 1" damping="3" name="right_bfoot_joint_z" pos="0 0 0" range="-15 5" stiffness="120" type="hinge"/>
            <geom axisangle="0 1 0 -15.4698604685" name="right_bfoot" pos=".03 0 -.097" size="0.046 .094" type="capsule"/>
          </body>
        </body>
      </body>
      <body name="right_fthigh" pos="0.4 -.09 0">
        <joint axis="1 0 0" damping="4.5" name="right_fthigh_joint_x" pos="0 0 0" range="-15 5" stiffness="180" type="hinge"/>
        <joint axis="0 -1 0" damping="4.5" name="right_fthigh_joint_y" pos="0 0 0" range="-40 60" stiffness="180" type="hinge"/>
        <joint axis="0 0 1" damping="4.5" name="right_fthigh_joint_z" pos="0 0 0" range="-20 10" stiffness="180" type="hinge"/>
        <geom axisangle="0 1 0 29.7938053468" name="right_fthigh" pos="-.07 0 -.12" size="0.055 .133" type="capsule"/>
        <body name="right_fshin" pos="-.14 0 -.24">
          <joint axis="1 0 0" damping="3" name="right_fshin_joint_x" pos="0 0 0" range="-1 1" stiffness="120" type="hinge"/>
          <joint axis="0 -1 0" damping="3" name="right_fshin_joint_y" pos="0 0 0" range="-50 70" stiffness="120" type="hinge"/>
          <joint axis="0 0 1" damping="3" name="right_fshin_joint_z" pos="0 0 0" range="-1 1" stiffness="120" type="hinge"/>
          <geom axisangle="0 1 0 -34.3774677078" name="right_fshin" pos=".065 0 -.09" size="0.046 .106" type="capsule"/>
        </body>
      </body>
      <body name="left_bthigh" pos="-.445 .12 0">
        <joint axis="-1 0 0" damping="6" name="left_bthigh_joint_x" pos="0 0 0" range="-10 0" stiffness="240" type="hinge"/>
        <joint axis="0 -1 0" damping="6" name="left_bthigh_joint_y" pos="0 0 0" range="-60 30" stiffness="240" type="hinge"/>
        <joint axis="0 0 -1" damping="6" name="left_bthigh_joint_z" pos="0 0 0" range="-15 5" stiffness="240" type="hinge"/>
        <geom axisangle="0 1 0 -217.7239621497" name="left_bthigh" pos=".1 0 -.13" size="0.06 .145" type="capsule"/>
      </body>
      <body name="left_fthigh" pos="0.4 .09 0">
        <joint axis="-1 0 0" damping="4.5" name="left_fthigh_joint_x" pos="0 0 0" range="-15 5" stiffness="180" type="hinge"/>
        <joint axis="0 -1 0" damping="4.5" name="left_fthigh_joint_y" pos="0 0 0" range="-40 60" stiffness="180" type="hinge"/>
        <joint axis="0 0 -1" damping="4.5" name="left_fthigh_joint_z" pos="0 0 0" range="-20 10" stiffness="180" type="hinge"/>
        <geom axisangle="0 1 0 29.7938053468" name="left_fthigh" pos="-.07 0 -.12" size="0.055 .133" type="capsule"/>
        <body name="left_fshin" pos="-.14 0 -.24">
          <joint axis="-1 0 0" damping="3" name="left_fshin_joint_x" pos="0 0 0" range="-1 1" stiffness="120" type="hinge"/>
          <joint axis="0 -1 0" damping="3" name="left_fshin_joint_y" pos="0 0 0" range="-50 70" stiffness="120" type="hinge"/>
          <joint axis="0 0 -1" damping="3" name="left_fshin_joint_z" pos="0 0 0" range="-1 1" stiffness="120" type="hinge"/>
          <geom axisangle="0 1 0 -34.3774677078" name="left_fshin" pos=".065 0 -.09" size="0.046 .106" type="capsule"/>
          <!-- <geom name="left_ffoot" type="sphere" size="0.06" pos="0.145 0 -0.22"/> -->
          <body name="left_ffoot" pos=".13 0 -.18">
            <joint axis="-1 0 0" damping="1.5" name="left_ffoot_joint_x" pos="0 0 0" range="-1 1" stiffness="60" type="hinge"/>
            <joint axis="0 -1 0" damping="1.5" name="left_ffoot_joint_y" pos="0 0 0" range="-30 30" stiffness="60" type="hinge"/>
            <joint axis="0 0 -1" damping="1.5" name="left_ffoot_joint_z" pos="0 0 0" range="-20 5" stiffness="60" type="hinge"/>
            <geom axisangle="0 1 0 -34.3774677078" name="left_ffoot" pos=".045 0 -.07" size="0.046 .07" type="capsule"/>
          </body>
        </body>
      </body>
    </body>
  </worldbody>
  <actuator>
    <motor gear="70" joint="upper_tail_joint_x" name="upper_tail_joint_x"/>
    <motor gear="70" joint="upper_tail_joint_y" name="upper_tail_joint_y"/>
    <motor gear="0" joint="upper_tail_joint_z" name="upper_tail_joint_z"/>

    <motor gear="120" joint="right_bthigh_joint_x" name="right_bthigh_joint_x"/>
    <motor gear="120" joint="right_bthigh_joint_y" name="right_bthigh_joint_y"/>
    <motor gear="120" joint="right_bthigh_joint_z" name="right_bthigh_joint_z"/>
    <motor gear="0" joint="right_bshin_joint_x" name="right_bshin_joint_x"/>
    <motor gear="90" joint="right_bshin_joint_y" name="right_bshin_joint_y"/>
    <motor gear="0" joint="right_bshin_joint_z" name="right_bshin_joint_z"/>
    <motor gear="0" joint="right_bfoot_joint_x" name="right_bfoot_joint_x"/>
    <motor gear="60" joint="right_bfoot_joint_y" name="right_bfoot_joint_y"/>
    <motor gear="60" joint="right_bfoot_joint_z" name="right_bfoot_joint_z"/>
    <motor gear="120" joint="right_fthigh_joint_x" name="right_fthigh_joint_x"/>
    <motor gear="120" joint="right_fthigh_joint_y" name="right_fthigh_joint_y"/>
    <motor gear="120" joint="right_fthigh_joint_z" name="right_fthigh_joint_z"/>
    <motor gear="0" joint="right_fshin_joint_x" name="right_fshin_joint_x"/>
    <motor gear="60" joint="right_fshin_joint_y" name="right_fshin_joint_y"/>
    <motor gear="0" joint="right_fshin_joint_z" name="right_fshin_joint_z"/>
    <motor gear="120" joint="left_bthigh_joint_x" name="left_bthigh_joint_x"/>
    <motor gear="120" joint="left_bthigh_joint_y" name="left_bthigh_joint_y"/>
    <motor gear="120" joint="left_bthigh_joint_z" name="left_bthigh_joint_z"/>
    <motor gear="120" joint="left_fthigh_joint_x" name="left_fthigh_joint_x"/>
    <motor gear="120" joint="left_fthigh_joint_y" name="left_fthigh_joint_y"/>
    <motor gear="120" joint="left_fthigh_joint_z" name="left_fthigh_joint_z"/>
    <motor gear="0" joint="left_fshin_joint_x" name="left_fshin_joint_x"/>
    <motor gear="60" joint="left_fshin_joint_y" name="left_fshin_joint_y"/>
    <motor gear="0" joint="left_fshin_joint_z" name="left_fshin_joint_z"/>
    <motor gear="0" joint="left_ffoot_joint_x" name="left_ffoot_joint_x"/>
    <motor gear="30" joint="left_ffoot_joint_y" name="left_ffoot_joint_y"/>
    <motor gear="30" joint="left_ffoot_joint_z" name="left_ffoot_joint_z"/>
  </actuator>
</mujoco>
